Workbook

Sheet Final Output Distribution
A1: Final Model Output Distribution
A2: Final Category | B2: Image Count | C2: Percentage of 2.5M Images | D2: Confidence Threshold
A3: animal | B3: 5221 | C3: =B3/'Waterfall Analyses'!$B$2 -> 0.0020881227 | D3: 0.5
A4: human | B4: 1368 | C4: =B4/'Waterfall Analyses'!$B$2 -> 0.00054712734 | D4: 0.3
A5: vehicle | B5: 334250 | C5: =B5/'Waterfall Analyses'!$B$2 -> 0.13368225 | D5: 0.3
B6: =SUM(B3:B5) -> 340839 | E6: Note: this 340K is not distinct images, for image has category Animal+Vehicle, this would count the same image twice.
A8: Another perspectives to see images might be tagged by multiple categories
B9: Final Category | C9: Image Count | D9: Percentage of 2.5M Images
B10: Animals | C10: 3516 | D10: =C10/$C$17 -> 0.010379275
B11: Animals, Vehicles | C11: 1939 | D11: =C11/$C$17 -> 0.0057239514
B12: Vehicles | C12: 331929 | D12: =C12/$C$17 -> 0.97985842
B13: Humans | C13: 985 | D13: =C13/$C$17 -> 0.0029077319
B14: Humans, Vehicles | C14: 380 | D14: =C14/$C$17 -> 0.0011217646
B15: Animals, Humans, Vehicles | C15: 2 | D15: =C15/$C$17 -> 5.9040242e-06
B16: Animals, Humans | C16: 1 | D16: =C16/$C$17 -> 2.9520121e-06
B17: Total | C17: =SUM(C10:C16) -> 338752 | D17: =SUM(D10:D16) -> 1
A20: Threshold analyses | B20: final_category_label | C20: tagged image count | D20: percentage of 2.5M images | E20: camera 4 image count | F20: camera 4 image percentage to tagged animal images | G20: filtered left image count | H20: percentage of 2.5M images | I20: Manual Validation Precision Estimate 100 images | J20: Manual Validation Precision Estimate 100 images
A21: Both>=0.8 | B21: animal | C21: 1149 | D21: =C21/'Waterfall Analyses'!$B$2 -> 0.00045953897 | E21: 146 | F21: =E21/C21 -> 0.12706701 | G21: =C21-E21 -> 1003 | H21: =G21/'Waterfall Analyses'!$B$2 -> 0.00040114673
A22: Both>=0.7 | B22: animal | C22: 3190 | D22: =C22/'Waterfall Analyses'!$B$2 -> 0.0012758306 | E22: 1595 | F22: =E22/C22 -> 0.5 | G22: 1595 | H22: =G22/'Waterfall Analyses'!$B$2 -> 0.00063791528
A23: Both>=0.6 | B23: animal | C23: 6405 | D23: =C23/'Waterfall Analyses'!$B$2 -> 0.0025616598 | E23: 3456 | F23: =E23/C23 -> 0.53957845 | G23: 2949 | H23: =G23/'Waterfall Analyses'!$B$2 -> 0.0011794434
A24: Both>=0.5 | B24: animal | C24: 10507 | D24: =C24/'Waterfall Analyses'!$B$2 -> 0.0042022419 | E24: 5286 | F24: =E24/C24 -> 0.50309318 | G24: 5221 | H24: =G24/'Waterfall Analyses'!$B$2 -> 0.0020881227 | I24: 0.63
A25: Both>=0.4 | B25: animal | C25: 15979 | D25: =C25/'Waterfall Analyses'!$B$2 -> 0.0063907513 | E25: 7373 | F25: =E25/C25 -> 0.46141811 | G25: 8606 | H25: =G25/'Waterfall Analyses'!$B$2 -> 0.0034419429
A26: Both>=0.3 | B26: animal | C26: 23825 | D26: =C26/'Waterfall Analyses'!$B$2 -> 0.0095287346 | E26: 10015 | F26: =E26/C26 -> 0.42035677 | G26: =C26-E26 -> 13810 | H26: =G26/'Waterfall Analyses'!$B$2 -> 0.0055232665
A27: Both>=0.2 | B27: animal | C27: 30107 | D27: =C27/'Waterfall Analyses'!$B$2 -> 0.012041201 | E27: 11930 | F27: =E27/C27 -> 0.39625336 | G27: =C27-E27 -> 18177 | H27: =G27/'Waterfall Analyses'!$B$2 -> 0.0072698346 | I27: 0.31 | J27: 0.37
A29: Notes: All tables were populated by Python script, so tables can be found in Python script output consoles

Sheet Duration Summary
A1: Major Steps with Breakdown | B1: CPU | C1: Current Process Duration | D1: Notes | E1: Notes | F1: Tanying's Notes
A2: Step 1. Setup Libraries | B2: - | C2: 1min 30seconds | D2: - | E2: Minimal difference
A3: Step 2. Load Manifest Table with Image Path and File Size | B3: - | D3: - | E3: Minimal difference | F3: previously 22h 53m on CPU cluster, now using metadata directly
A4: Processing Time | C4: 20min
A5: Output to Catalog Volume table | C5: 15min
A6: Step 3. Add TM indicator
A7: Identify all the date folders for batch processing | C7: 6min
A8: Process TM info output to Volume Table | C8: 10hr
A9: Join TM table with Manifest table | C9: 3s
A10: Write combined cleaned table to Catalog Volume | C10: 6s
A11: Step 4. Apply Megadtector v5 binary model on filtered images
A12: Load model | C12: 5s
A13: Process V5 and save binary output to Volume Table | C13: 1day14hours | G13: Rewrote functions to avoid:
A14: Step 5. Run Megadetector Stack models on included images
A15: Run Megadetector v5 detailed model on not filtered images | C15: 4day | F15: on average, 4min per 1000 images
A16: Run Megadetector v6-yolo9c detailed model on not filtered images | C16: 1day19hours | F16: on average, 2min per 1000 images
A17: Step 6. Rules to exclude False Postives
A18: Combine Megadetector v5 and v6 results | C18: 2min
A19: Apply confidence threshold rules to exclude false positives | C19: 2min
A20: Post-processing filter exclude images comes from Camera 4 | C20: 2min
A21: Step 7. Output to JSON/Manifest Table
A22: a. Volume table in catalog with 2.4 million images went through the model with confidence score and detections, if not going through model, just confidence/category/detection results being 'NULL', 'pre-filtered'> attributes per step excluded reason | C22: 30min | D22: eta:10min
A23: b. JSON output for the ones labeled as vehicles and animals | C23: included in the Volume table as last column | D23: eta:2min | E23: /Volumes/meadowbank_prod/remote_cameras/mbk_remote_cameras_blob/results/2024_TWS
A24: c. Vehicle report count (Are barrel trucks should be excldued from the Vehicle folder/ also Vehicle count?) | D24: eta: after e is ready, should be fast, 5min
A25: d. copy all the animal pictures with bounding box into separate folder | C25: 22min for Animals, 1hr30min for Vehicles, 10min for Human | D25: eta: 10hr
A26: e. Clustering animals -> goes to additional column event_id | D26: eta: 1hr
A27: f. flow chart | C27: 2min

Sheet Waterfall Analyses
A1: Base folder: "/Volumes/meadowbank_prod/remote_cameras/mbk_remote_cameras_blob/2024/"
A2: Image count: | B2: 2500332
A4: Step 1: Create Manifest table | B4: Filtered Image Count | C4: Percentage of Total Image Count | D4: Notes/Concerns
A5: Get image paths into manifest table | B5: 0 | C5: 0 | D5: without filesize, this can be done within 1 hr
A7: Step 2: Pre-Processing Filters | B7: Filtered Image Count | C7: Percentage of Total Image Count | D7: Notes/Concerns
A8: Timed images | B8: 282014 | C8: =B8/B2 -> 0.11279062 | D8: 2.5hr on GPU cluster by date folder as batch
A9: File size (<=105KB) | B9: 63436 | C9: =B9/B2 -> 0.025371031 | D9: 35min using metadata logic
A10: Total Excluded Images | B10: 326800 | C10: =B10/B2 -> 0.13070264 | D10: Because B9 and B9 has small overlap so the total is not the summation
A12: Step 3: Confirm Pre-processing filtered images should truly be filtered out
A13: MegaDetector v5 - BINARY pre-trained model to quickly identify non-animal images | B13: 91098 | C13: =B13/B2 -> 0.036434362 | D13: 0.2 confidence level was used to detect animal (class 0), According to documentation, MDv5a was trained on of “additional data” including small birds, rodents, and improved false-positive filtering, 1day14hrs
A15: Total Count of Images were not excluded by pre-processing filters | B15: 2173531 | C15: =B15/B2 -> 0.86929696
A17: Images with high animal confidence from step 2 (B2-B12+B18) | B17: 1279887 | C17: =B17/B2 -> 0.51188682
A18: Step 4: Total Count of Images for Animal Detection (Sample) | B18: Tagged as animal/human/vehicle (conf>=0.2) | C18: Percentage of Processed Images | D18: Tagged as animal (conf>=0.2 & category='animal') | E18: Animal Percentage of the Processed Images | F18: Notes/Concerns
A19: MegaDetector v5a | B19: 75026 | C19: =B19/125000 -> 0.600208 | D19: 18076 | E19: =D19/125000 -> 0.144608 | F19: MegaDetector v5 is a YOLOv5 model while v6b-yolo9c is a ultralytics model, 20min per batch, 8hr run 125,000 images
A20: MegaDetector v6b-yolo9c | B20: 72975 | C20: =B20/155000 -> 0.47080645 | D20: 10613 | E20: =10613/155000 -> 0.068470968 | F20: 14hr run 155,000 images, slow also because output to json file
A22: Step 5: Total Count of Animal Images (1.3 million full dataset) | B22: Tagged as animal/human/vehicle (conf>=0.5) | C22: Percentage of Processed Images | D22: Tagged as animal(conf>=0.5 & category='animal') | E22: Animal Percentage of Total Images | F22: Tagged as animal(conf>=0.4 & category='animal') | G22: Animal Percentage of Total Images | H22: Tagged as animal(conf>=0.3 & category='animal') | I22: Animal Percentage of Total Images | J22: Tagged as animal(conf>=0.2 & category='animal') | K22: Animal Percentage of Total Images
A23: MegaDetector v5a | B23: 617111 | C23: =B23/B17 -> 0.48216053 | D23: 45765 | E23: =D23/B2 -> 0.018303569 | F23: 60824 | G23: =F23/B2 -> 0.024326369 | H23: 81031 | I23: =H23/B2 -> 0.032408096 | J23: 99572 | K23: =J23/B2 -> 0.039823511
A24: MegaDetector v6b-yolo9c | B24: 373385 | C24: =B24/B17 -> 0.29173279 | D24: 27832 | E24: =D24/B2 -> 0.011131322 | F24: 43803 | G24: =F24/B2 -> 0.017518873 | H24: 67256 | I24: =H24/B2 -> 0.026898828 | J24: 84213 | K24: =J24/B2 -> 0.033680727
A26: Step 5: Total Count of Vehicle Images (1.3 million full dataset) | B26: Tagged as Vehicle/human/vehicle (conf>=0.5) | C26: Percentage of Processed Images | D26: Tagged as Vehicle(conf>=0.5 & category='Vehicle') | E26: Vehicle Percentage of Total Images | F26: Tagged as Vehicle(conf>=0.4 & category='Vehicle') | G26: Vehicle Percentage of Total Images | H26: Tagged as Vehicle(conf>=0.3 & category='Vehicle') | I26: Vehicle Percentage of Total Images | J26: Tagged as Vehicle(conf>=0.2 & category='Vehicle') | K26: Vehicle Percentage of Total Images
A27: MegaDetector v5a | B27: 617111 | C27: 0.48216392 | D27: 576304 | E27: =D27/B2 -> 0.23049099 | F27: 611829 | G27: =F27/B2 -> 0.2446991 | H27: 645807 | I27: =H27/B2 -> 0.2582885 | J27: 668298 | K27: =J27/B2 -> 0.2672837
A28: MegaDetector v6b-yolo9c | B28: 373385 | C28: 0.29173484 | D28: 352567 | E28: =D28/B2 -> 0.14100807 | F28: 388460 | G28: =F28/B2 -> 0.15536337 | H28: 425971 | I28: =H28/B2 -> 0.17036578 | J28: 446246 | K28: =J28/B2 -> 0.1784747
A30: Step 6: Combine Megadetector 5a and 6b-yolo9c Animal Images | D30: Tagged as animal(conf>=0.5 & category='animal') | E30: Animal Percentage of Total Images | F30: Tagged as animal(conf>=0.4 & category='animal') | G30: Animal Percentage of Total Images | H30: Tagged as animal(conf>=0.3 & category='animal') | I30: Animal Percentage of Total Images | J30: Tagged as animal(conf>=0.2 & category='animal') | K30: Animal Percentage of Total Images
A31: When v5a and v6b-yolo9c share consistent results (one image can be tagged with more than one category) | D31: 16693 | E31: =D31/B2 -> 0.0066763134 | F31: 24292 | G31: =F31/B2 -> 0.0097155098 | H31: 36902 | I31: =H31/B2 -> 0.01475884 | J31: 48479 | K31: =J31/B2 -> 0.019389025
F32: =F31/F24 -> 0.55457389
A33: Step 6: Combine Megadetector 5a and 6b-yolo9c Vehicle Images | D33: Tagged as Vehicle(conf>=0.5 & category='Vehicle') | E33: Vehicle Percentage of Total Images | F33: Tagged as Vehicle(conf>=0.4 & category='Vehicle') | G33: Vehicle Percentage of Total Images | H33: Tagged as Vehicle(conf>=0.3 & category='Vehicle') | I33: Vehicle Percentage of Total Images | J33: Tagged as Vehicle(conf>=0.2 & category='Vehicle') | K33: Vehicle Percentage of Total Images
A34: When v5a and v6b-yolo9c share consistent results (one image can be tagged with more than one category) | D34: 342009 | E34: =D34/B2 -> 0.13678543 | F34: 383293 | G34: =F34/B2 -> 0.15329684 | H34: 430903 | I34: =H34/B2 -> 0.17233831 | J34: 460850 | K34: =J34/B2 -> 0.18431552
F35: =F34/F28 -> 0.98669876
A36: Proposal, Ideally:
A37: 1. Combine v5a with v6b
A38: 2. When inconsistent, if V6b is not confident about animal(<0.4) and v5a is 0, then listen to v5, help us remove false positives
A39: 3. When inconsistent, if V6b is not confident about vehicle (<0.4) and v5a is 0, then listen to v6, help us remove false positives
A40: 4. When inconsistnent category, if V6b is very confident and v5a is very confident too, then listen to v5a
A41: 5. When inconsistent, if V6b is very confident on vehicle and v5a is not confident, then listen 5a
A42: 6. raise confidence threshold, when both not confidence (<0.6), nothing
A43: 7. When both confident, probably they are right
A46: Threshold analyses | B46: final_category_label | C46: tagged image count | D46: percentage of 2.5M images | E46: camera 4 image count | F46: camera 4 image percentage to tagged animal images | G46: filtered left image count | H46: percentage of 2.5M images | I46: Manual Validation Precision Estimate 100 images
A47: Both>=0.8 | B47: animal | C47: 1149 | D47: =C47/'Waterfall Analyses'!$B$2 -> 0.00045953897 | E47: 146 | F47: =E47/C47 -> 0.12706701 | G47: =C47-E47 -> 1003 | H47: =G47/'Waterfall Analyses'!$B$2 -> 0.00040114673
A48: Both>=0.7 | B48: animal | C48: 3190 | D48: =C48/'Waterfall Analyses'!$B$2 -> 0.0012758306 | E48: 1595 | F48: =E48/C48 -> 0.5 | G48: 1595 | H48: =G48/'Waterfall Analyses'!$B$2 -> 0.00063791528
A49: Both>=0.6 | B49: animal | C49: 6405 | D49: =C49/'Waterfall Analyses'!$B$2 -> 0.0025616598 | E49: 3456 | F49: =E49/C49 -> 0.53957845 | G49: 2949 | H49: =G49/'Waterfall Analyses'!$B$2 -> 0.0011794434
A50: Both>=0.5 | B50: animal | C50: 10507 | D50: =C50/'Waterfall Analyses'!$B$2 -> 0.0042022419 | E50: 5286 | F50: =E50/C50 -> 0.50309318 | G50: 5221 | H50: =G50/'Waterfall Analyses'!$B$2 -> 0.0020881227 | I50: 0.63
...

Sheet Flow Chart

Sheet Before vs. After Comparison
A1: Before:
A2: Threshold analyses | B2: final_category_label | C2: image count | D2: percentage of 2.5M images | E2: Manual Validation Precision Estimation | F2: Manual Validation Precision Estimation 2nd Batch | G2: Manual Validation Precision Estimate 100 images
A3: >=0.8 | B3: animal | C3: 6129 | D3: =C3/2500329 -> 0.0024512774 | E3: 0.3 | F3: 0.2 | G3: 0.16
A4: >=0.7 | B4: animal | C4: 13746 | D4: =C4/2500329 -> 0.0054976765 | E4: 0 | F4: 0
A5: >=0.6 | B5: animal | C5: 24452 | D5: =C5/2500329 -> 0.009779513 | E5: 0 | F5: 0
A6: >=0.5 | B6: animal | C6: 39375 | D6: =C6/2500329 -> 0.015747928 | E6: 0 | F6: 0
A7: >=0.4 | B7: animal | C7: 60525 | D7: =C7/2500329 -> 0.024206814 | E7: 0.1 | F7: 0
A8: >=0.3 | B8: animal | C8: 92613 | D8: =C8/2500329 -> 0.037040325 | E8: 0 | F8: 0
A9: >=0.2 | B9: animal | C9: 140614 | D9: =C9/2500329 -> 0.056238199 | E9: 0 | F9: 0
A11: Before: Model exclusion + BarrelCoords not NULL + FlagCoords not NULL + SmallTrucksCoords not NULL
A13: After:
A14: Threshold analyses | B14: final_category_label | C14: image count | D14: percentage of 2.5M images | E14: Manual Validation Precision Estimation 1st Batch | F14: Manual Validation Precision Estimation 2nd Batch | G14: Manual Validation Precision Estimate 100 images
A15: Both>=0.8 | B15: animal | C15: 1159 | D15: 0.00046353844 | E15: 1 | F15: 1
A16: Both>=0.7 | B16: animal | C16: 3246 | D16: 0.0012982276 | E16: 0.7 | F16: 0.6
A17: Both>=0.6 | B17: animal | C17: 6528 | D17: 0.0026108533 | E17: 0.3 | F17: 0.6
A18: Both>=0.5 | B18: animal | C18: 10507 | D18: =C18/'Waterfall Analyses'!$B$2 -> 0.0042022419 | E18: 0.5 | F18: 0.6 | G18: 0.44
A19: Both>=0.4 | B19: animal | C19: 16490 | D19: 0.0065951242 | E19: 0.4 | F19: 0.5
A20: Both>=0.3 | B20: animal | C20: 24885 | D20: 0.0099526783 | E20: 0.2 | F20: 0.3
A21: Both>=0.2 | B21: animal | C21: 31660 | D21: 0.012662318 | E21: 0.1 | F21: 0.1
A24: If exclude all images from Camera 4
A25: Threshold analyses | B25: final_category_label | C25: tagged image count | D25: percentage of 2.5M images | E25: camera 4 image count | F25: camera 4 image percentage to tagged animal images | G25: filtered left image count | H25: percentage of 2.5M images | I25: Manual Validation Precision Estimate 100 images | J25: Manual Validation Precision Estimate 100 images
A26: Both>=0.8 | B26: animal | C26: 1149 | D26: =C26/'Waterfall Analyses'!$B$2 -> 0.00045953897 | E26: 146 | F26: =E26/C26 -> 0.12706701 | G26: =C26-E26 -> 1003 | H26: =G26/'Waterfall Analyses'!$B$2 -> 0.00040114673
A27: Both>=0.7 | B27: animal | C27: 3190 | D27: =C27/'Waterfall Analyses'!$B$2 -> 0.0012758306 | E27: 1595 | F27: =E27/C27 -> 0.5 | G27: 1595 | H27: =G27/'Waterfall Analyses'!$B$2 -> 0.00063791528
A28: Both>=0.6 | B28: animal | C28: 6405 | D28: =C28/'Waterfall Analyses'!$B$2 -> 0.0025616598 | E28: 3456 | F28: =E28/C28 -> 0.53957845 | G28: 2949 | H28: =G28/'Waterfall Analyses'!$B$2 -> 0.0011794434
A29: Both>=0.5 | B29: animal | C29: 10507 | D29: =C29/'Waterfall Analyses'!$B$2 -> 0.0042022419 | E29: 5286 | F29: =E29/C29 -> 0.50309318 | G29: 5221 | H29: =G29/'Waterfall Analyses'!$B$2 -> 0.0020881227 | I29: 0.63 | K29: =I29*G29 -> 3289.23
A30: Both>=0.4 | B30: animal | C30: 15979 | D30: =C30/'Waterfall Analyses'!$B$2 -> 0.0063907513 | E30: 7373 | F30: =E30/C30 -> 0.46141811 | G30: 8606 | H30: =G30/'Waterfall Analyses'!$B$2 -> 0.0034419429
A31: Both>=0.3 | B31: animal | C31: 23825 | D31: =C31/'Waterfall Analyses'!$B$2 -> 0.0095287346 | E31: 10015 | F31: =E31/C31 -> 0.42035677 | G31: =C31-E31 -> 13810 | H31: =G31/'Waterfall Analyses'!$B$2 -> 0.0055232665
A32: Both>=0.2 | B32: animal | C32: 30107 | D32: =C32/'Waterfall Analyses'!$B$2 -> 0.012041201 | E32: 11930 | F32: =E32/C32 -> 0.39625336 | G32: =C32-E32 -> 18177 | H32: =G32/'Waterfall Analyses'!$B$2 -> 0.0072698346 | I32: 0.31 | J32: 0.37 | K32: =I32*G32 -> 5634.87
A34: If assign motion score to group of images | E34: If assign motion score to group of images with conf<0.5
A35: Static/Non-Static analyses | B35: Image Count | C35: Percentage | E35: Static/Non-Static analyses | F35: Image Count | G35: Percentage
A36: total images with adjacent neighbor | B36: 8720 | C36: =B36/G32 -> 0.47972713 | E36: total images with adjacent neighbor | F36: 8720 | G36: =C36 -> 0.47972713
A37: df_motion | B37: 5707 | E37: df_motion | F37: 5707
A38: static | B38: =7285-625 -> 6660 | C38: =B38/B36 -> 0.76376147 | E38: static | F38: 2057 | G38: =F38/F36 -> 0.2358945
A39: nonstatic | B39: 2050 | C39: =B39/B36 -> 0.23509174 | E39: nonstatic | F39: =F36-F38 -> 6663 | G39: =F39/F36 -> 0.7641055
A40: common | B40: 625
A43: Threshold analyses | B43: final_category_label | C43: tagged image count | D43: percentage of 2.5M images | E43: camera 4 image count | F43: camera 4 image percentage to tagged animal images | G43: filtered left image count | H43: percentage of 2.5M images | I43: exclude static images | J43: filtered left image count | K43: Percentage of 2.5M images | L43: Manual Validation Precision Estimate 100 images
A44: Both>=0.2 | B44: animal | C44: 30107 | D44: =C44/'Waterfall Analyses'!$B$2 -> 0.012041201 | E44: 11930 | F44: =E44/C44 -> 0.39625336 | G44: =C44-E44 -> 18177 | H44: =G44/'Waterfall Analyses'!$B$2 -> 0.0072698346 | I44: 2057 | J44: =G44-I44 -> 16120 | K44: =J44/2500332 -> 0.0064471438 | L44: 0.26
A48: Threshold analyses | B48: filtered left image count | C48: percentage of 2.5M images | D48: Manual Validation Precision Estimate 100 images
A49: Both>=0.8 | B49: 1003 | C49: 0.00040114673
A50: Both>=0.7 | B50: 1595 | C50: 0.00063791528
...

Sheet Percentage of real animals
A1: image_path | B1: contains_animals
A2: /Volumes/meadowbank_prod/remote_cameras/mbk_remote_cameras_blob/2024/FirstPart/Camera 13/2024-02-06/RCNX8433.JPG | B2: N
A3: /Volumes/meadowbank_prod/remote_cameras/mbk_remote_cameras_blob/2024/FirstPart/Camera 14/2024-02-06/RCNX1441.JPG | B3: N
A4: /Volumes/meadowbank_prod/remote_cameras/mbk_remote_cameras_blob/2024/SecondPart/Camera/Camera 7/2024-09-28/100RECNX/RCNX0096.JPG | B4: N
A5: /Volumes/meadowbank_prod/remote_cameras/mbk_remote_cameras_blob/2024/FirstPart/Camera 4/2024-08-24/100RECNX/RCNX1045.JPG | B5: N
A6: /Volumes/meadowbank_prod/remote_cameras/mbk_remote_cameras_blob/2024/FirstPart/Camera 14/2024-08-24/100RECNX/RCNX0699.JPG | B6: N
A7: /Volumes/meadowbank_prod/remote_cameras/mbk_remote_cameras_blob/2024/FirstPart/Camera 6/2024-02-15/100RECNX/RCNX9753.JPG | B7: N
A8: /Volumes/meadowbank_prod/remote_cameras/mbk_remote_cameras_blob/2024/FirstPart/Camera 12/2024-06-08/100RECNX/RCNX1206.JPG | B8: N
A9: /Volumes/meadowbank_prod/remote_cameras/mbk_remote_cameras_blob/2024/FirstPart/Camera 13/2024-06-04/100RECNX/RCNX0010.JPG | B9: N
A10: /Volumes/meadowbank_prod/remote_cameras/mbk_remote_cameras_blob/2024/FirstPart/Camera 4/2024-02-15/100RECNX/RCNX1327.JPG | B10: N
A11: /Volumes/meadowbank_prod/remote_cameras/mbk_remote_cameras_blob/2024/FirstPart/Camera 19/2024-07-01/100RECNX/RCNX6895.JPG | B11: N
A12: /Volumes/meadowbank_prod/remote_cameras/mbk_remote_cameras_blob/2024/FirstPart/Camera 4/2024-05-29/101RECNX/RCNX1875.JPG | B12: N
... A1601: /Volumes/meadowbank_prod/remote_cameras/mbk_remote_cameras_blob/2024/FirstPart/Camera 13/2024-07-06/100RECNX/RCNX1086.JPG | B1601: N

Sheet Animal Images by Camera
A1: camera_folder | B1: animal_images | C1: number_of_images | D1: percentage
A2: Camera 13 | B2: 367 | C2: 377279 | D2: 0.00097275491 | F2: On average, animal images tagged by model is 0.22%, before excluding from camera 4, is 0.44%
A3: Camera 4 | B3: 0 | C3: 357550 | D3: 0
A4: Camera 14 | B4: 2361 | C4: 354607 | D4: 0.006658075
A5: Camera 19 | B5: 251 | C5: 295869 | D5: 0.00084834842
A6: Camera 11 | B6: 165 | C6: 204494 | D6: 0.00080686964
A7: Camera 15 | B7: 171 | C7: 133979 | D7: 0.0012763194
A8: Camera 17 | B8: 383 | C8: 131337 | D8: 0.0029161622
A9: Camera 12 | B9: 480 | C9: 119045 | D9: 0.0040320887
A10: Camera 10 | B10: 40 | C10: 109425 | D10: 0.00036554718
A11: Camera 1 | B11: 137 | C11: 102836 | D11: 0.0013322183
A12: Camera 18 | B12: 423 | C12: 96173 | D12: 0.0043983239
A13: Camera 6 | B13: 82 | C13: 68216 | D13: 0.001202064
A14: Camera 16 | B14: 30 | C14: 41684 | D14: 0.0007197006
... A21: Camera 8 | B21: 68 | C21: 8026 | D21: 0.0084724645
A22: Total | B22: 5221 | C22: 2500332

Sheet Sandeep Time Range Analyses
A2: Camera Folder | B2: Image Count | C2: Hours having images >= 500 | D2: Respective Precision(sample 50 images)(%) | E2: Respective Image Counts | F2: Total | G2: Statement
A3: camera 14 | B3: 6951 | C3: 13, 14, 15, 16 | D3: 0.0, 0.0, 0.0, 0.0 | E3: 710, 1091, 1132, 671 | F3: 3604 | G3: Small BB far away
A4: camera 19 | B4: 6266 | C4: 18, 19, 20, 21, 22, 23 | D4: 0.0, 0.0, 0.0, 0.0, 0.0, 0.0 | E4: 563, 1199, 722, 716, 718, 597 | F4: 4515 | G4: Sun Glare
A5: camera 13 | B5: 5014 | C5: 12, 21, 22 | D5: 92, 90, 0.0 | E5: 925, 1468, 597 | F5: 2990 | G5: Birds, caribou/deer, trucks mostly
A6: camera 17 | B6: 3535 | C6: 02, | D6: 98 | E6: 2566 | F6: 2566 | G6: deer
A7: camera 12 | B7: 3160
A8: camera 18 | B8: 3096 | C8: 02, 06, | D8: 98, 98 | E8: 1202, 946 | F8: 2148 | G8: deer
A9: camera 11 | B9: 1754 | C9: 18 | D9: 96 | E9: 449 | F9: 449 | G9: yak
A10: camera 15 | B10: 867
A11: camera 1 | B11: 840
A12: camera 20 | B12: 705 | C12: 17 | D12: 100 | E12: 335 | F12: 335 | G12: yak
A13: camera 10 | B13: 354
A14: camera 8 | B14: 276
A15: camera 6 | B15: 238
A16: camera 16 | B16: 130
A17: camera 2 | B17: 121
A18: camera 7 | B18: 116
A19: camera 9 | B19: 32
A20: camera 3 | B20: 24
A21: Total | B21: =SUM(B3:B20) -> 33479 | F21: =SUM(F3:F20) -> 16607
E22: Animal | F22: 7891
E23: NON-Animal | F23: 8716

Sheet Post-processing Filter Camera 4
A1: 1. All images from Camera 4

Sheet Model_Validation_0.2
A1: image_path | B1: contains_animals
A2: /Volumes/meadowbank_prod/remote_cameras/mbk_remote_cameras_blob/2024/FirstPart/Camera 11/2024-07-06/100RECNX/RCNX0327.JPG | B2: Y
A3: /Volumes/meadowbank_prod/remote_cameras/mbk_remote_cameras_blob/2024/FirstPart/Camera 14/2024-08-24/100RECNX/RCNX3573.JPG
A4: /Volumes/meadowbank_prod/remote_cameras/mbk_remote_cameras_blob/2024/SecondPart/Camera/Camera 12/2024-09-14/100RECNX/RCNX0001.JPG
A5: /Volumes/meadowbank_prod/remote_cameras/mbk_remote_cameras_blob/2024/FirstPart/Camera 17/2024-08-08/100RECNX/RCNX0188.JPG | B5: Y
A6: /Volumes/meadowbank_prod/remote_cameras/mbk_remote_cameras_blob/2024/FirstPart/Camera 19/2024-06-08/100RECNX/RCNX5714.JPG | B6: Y
A7: /Volumes/meadowbank_prod/remote_cameras/mbk_remote_cameras_blob/2024/FirstPart/Camera 11/2024-07-06/100RECNX/RCNX0327.JPG | B7: Y
A8: /Volumes/meadowbank_prod/remote_cameras/mbk_remote_cameras_blob/2024/FirstPart/Camera 18/2024-08-08/100RECNX/RCNX0324.JPG
A9: /Volumes/meadowbank_prod/remote_cameras/mbk_remote_cameras_blob/2024/FirstPart/Camera 19/2024-07-13/100RECNX/RCNX2479.JPG
A10: /Volumes/meadowbank_prod/remote_cameras/mbk_remote_cameras_blob/2024/FirstPart/Camera 14/2024-06-24/102RECNX/RCNX5982.JPG
A11: /Volumes/meadowbank_prod/remote_cameras/mbk_remote_cameras_blob/2024/SecondPart/Camera/Camera 7/2024-10-27/100RECNX/RCNX0390.JPG | B11: Y
A12: /Volumes/meadowbank_prod/remote_cameras/mbk_remote_cameras_blob/2024/FirstPart/Camera 14/2024-08-24/101RECNX/RCNX1752.JPG
A13: /Volumes/meadowbank_prod/remote_cameras/mbk_remote_cameras_blob/2024/FirstPart/Camera 13/2024-05-05/100RECNX/RCNX0356.JPG | B13: Y
A14: /Volumes/meadowbank_prod/remote_cameras/mbk_remote_cameras_blob/2024/FirstPart/Camera 18/2024-08-08/100RECNX/RCNX0107.JPG | B14: Y
A15: /Volumes/meadowbank_prod/remote_cameras/mbk_remote_cameras_blob/2024/FirstPart/Camera 13/2024-05-05/100RECNX/RCNX0393.JPG | B15: Y
A16: /Volumes/meadowbank_prod/remote_cameras/mbk_remote_cameras_blob/2024/SecondPart/Camera/Camera 13/2024-09-14/100RECNX/RCNX3098.JPG | B16: Y
A17: /Volumes/meadowbank_prod/remote_cameras/mbk_remote_cameras_blob/2024/FirstPart/Camera 14/2024-08-24/101RECNX/RCNX4071.JPG
A18: /Volumes/meadowbank_prod/remote_cameras/mbk_remote_cameras_blob/2024/FirstPart/Camera 19/2024-06-24/100RECNX/RCNX1227.JPG
A19: /Volumes/meadowbank_prod/remote_cameras/mbk_remote_cameras_blob/2024/FirstPart/Camera 13/2024-06-08/100RECNX/RCNX9030.JPG | B19: Y
A20: /Volumes/meadowbank_prod/remote_cameras/mbk_remote_cameras_blob/2024/FirstPart/Camera 19/2024-06-24/101RECNX/RCNX3858.JPG
A21: /Volumes/meadowbank_prod/remote_cameras/mbk_remote_cameras_blob/2024/FirstPart/Camera 19/2024-06-04/100RECNX/RCNX7192.JPG
A22: /Volumes/meadowbank_prod/remote_cameras/mbk_remote_cameras_blob/2024/FirstPart/Camera 17/2024-08-08/100RECNX/RCNX0334.JPG | B22: y
A23: /Volumes/meadowbank_prod/remote_cameras/mbk_remote_cameras_blob/2024/SecondPart/Camera/Camera 14/2024-09-21/100RECNX/RCNX0315.JPG
A24: /Volumes/meadowbank_prod/remote_cameras/mbk_remote_cameras_blob/2024/SecondPart/Camera/Camera 14/2024-08-31/100RECNX/RCNX1215.JPG
A25: /Volumes/meadowbank_prod/remote_cameras/mbk_remote_cameras_blob/2024/FirstPart/Camera 14/2024-06-24/101RECNX/RCNX2554.JPG
A26: /Volumes/meadowbank_prod/remote_cameras/mbk_remote_cameras_blob/2024/SecondPart/Camera/Camera 14/2024-09-14/100RECNX/RCNX0130.JPG
A27: /Volumes/meadowbank_prod/remote_cameras/mbk_remote_cameras_blob/2024/FirstPart/Camera 11/2024-08-24/101RECNX/RCNX2118.JPG
A28: /Volumes/meadowbank_prod/remote_cameras/mbk_remote_cameras_blob/2024/FirstPart/Camera 19/2024-08-08/100RECNX/RCNX9601.JPG
A29: /Volumes/meadowbank_prod/remote_cameras/mbk_remote_cameras_blob/2024/FirstPart/Camera 14/2024-08-24/100RECNX/RCNX9547.JPG
A30: /Volumes/meadowbank_prod/remote_cameras/mbk_remote_cameras_blob/2024/FirstPart/Camera 17/2024-08-08/100RECNX/RCNX0212.JPG | B30: Y
A31: /Volumes/meadowbank_prod/remote_cameras/mbk_remote_cameras_blob/2024/FirstPart/Camera 17/2024-08-08/100RECNX/RCNX0187.JPG | B31: Y
A32: /Volumes/meadowbank_prod/remote_cameras/mbk_remote_cameras_blob/2024/FirstPart/Camera 12/2024-05-20/101RECNX/RCNX1844.JPG
A33: /Volumes/meadowbank_prod/remote_cameras/mbk_remote_cameras_blob/2024/FirstPart/Camera 19/2024-06-08/100RECNX/RCNX7745.JPG
A34: /Volumes/meadowbank_prod/remote_cameras/mbk_remote_cameras_blob/2024/FirstPart/Camera 13/2024-06-08/100RECNX/RCNX8954.JPG | B34: Y
A35: /Volumes/meadowbank_prod/remote_cameras/mbk_remote_cameras_blob/2024/FirstPart/Camera 14/2024-08-24/100RECNX/RCNX0193.JPG
A36: /Volumes/meadowbank_prod/remote_cameras/mbk_remote_cameras_blob/2024/FirstPart/Camera 17/2024-08-08/100RECNX/RCNX0236.JPG | B36: Y
A37: /Volumes/meadowbank_prod/remote_cameras/mbk_remote_cameras_blob/2024/FirstPart/Camera 19/2024-06-24/100RECNX/RCNX0615.JPG
A38: /Volumes/meadowbank_prod/remote_cameras/mbk_remote_cameras_blob/2024/SecondPart/Camera/Camera 20/2024-10-19/100RECNX/RCNX0062.JPG
A39: /Volumes/meadowbank_prod/remote_cameras/mbk_remote_cameras_blob/2024/SecondPart/Camera/Camera 14/2024-10-19/100RECNX/RCNX3551.JPG
A40: /Volumes/meadowbank_prod/remote_cameras/mbk_remote_cameras_blob/2024/FirstPart/Camera 17/2024-08-08/100RECNX/RCNX0207.JPG | B40: Y
...

Sheet Model_Validation_0.5
A1: image_path | B1: contains_animals | C1: contains_triangle
A2: /Volumes/meadowbank_prod/remote_cameras/mbk_remote_cameras_blob/2024/FirstPart/Camera 4/2024-04-23/DCIM/102RECNX/RCNX5742.JPG | B2: N | C2: Y | D2: Row Labels | E2: Count of image_path | F2: Current Precision | G2: Potential Improvement
A3: /Volumes/meadowbank_prod/remote_cameras/mbk_remote_cameras_blob/2024/FirstPart/Camera 17/2024-08-08/100RECNX/RCNX0289.JPG | B3: Y | D3: N | E3: 56
A4: /Volumes/meadowbank_prod/remote_cameras/mbk_remote_cameras_blob/2024/FirstPart/Camera 18/2024-08-08/100RECNX/RCNX0321.JPG | B4: Y | D4: Y | E4: 44 | F4: =E4/E6 -> 0.44 | G4: =E4/(E6-E9) -> 0.62857143
A5: /Volumes/meadowbank_prod/remote_cameras/mbk_remote_cameras_blob/2024/FirstPart/Camera 4/2024-04-23/DCIM/101RECNX/RCNX3108.JPG | B5: N | C5: Y | D5: (blank)
A6: /Volumes/meadowbank_prod/remote_cameras/mbk_remote_cameras_blob/2024/FirstPart/Camera 4/2024-04-23/DCIM/102RECNX/RCNX2324.JPG | B6: N | C6: Y | D6: Grand Total | E6: 100
A7: /Volumes/meadowbank_prod/remote_cameras/mbk_remote_cameras_blob/2024/FirstPart/Camera 4/2024-04-23/DCIM/104RECNX/RCNX4210.JPG | B7: N | C7: Y
A8: /Volumes/meadowbank_prod/remote_cameras/mbk_remote_cameras_blob/2024/FirstPart/Camera 4/2024-04-23/DCIM/102RECNX/RCNX0924.JPG | B8: N | C8: Y | D8: Row Labels | E8: Count of contains_triangle
A9: /Volumes/meadowbank_prod/remote_cameras/mbk_remote_cameras_blob/2024/SecondPart/Camera/Camera 14/2024-09-14/101RECNX/RCNX1438.JPG | B9: N | D9: Y | E9: 30
A10: /Volumes/meadowbank_prod/remote_cameras/mbk_remote_cameras_blob/2024/FirstPart/Camera 4/2024-04-23/DCIM/101RECNX/RCNX8428.JPG | B10: N | C10: Y
A11: /Volumes/meadowbank_prod/remote_cameras/mbk_remote_cameras_blob/2024/FirstPart/Camera 17/2024-08-08/100RECNX/RCNX0187.JPG | B11: Y
A12: /Volumes/meadowbank_prod/remote_cameras/mbk_remote_cameras_blob/2024/FirstPart/Camera 19/2024-07-01/100RECNX/RCNX0312.JPG | B12: N
A13: /Volumes/meadowbank_prod/remote_cameras/mbk_remote_cameras_blob/2024/FirstPart/Camera 4/2024-04-23/DCIM/102RECNX/RCNX0980.JPG | B13: N | C13: Y
A14: /Volumes/meadowbank_prod/remote_cameras/mbk_remote_cameras_blob/2024/FirstPart/Camera 19/2024-06-24/102RECNX/RCNX1247.JPG | B14: Y
A15: /Volumes/meadowbank_prod/remote_cameras/mbk_remote_cameras_blob/2024/FirstPart/Camera 6/2024-04-22/100RECNX/RCNX0148.JPG | B15: Y
A16: /Volumes/meadowbank_prod/remote_cameras/mbk_remote_cameras_blob/2024/FirstPart/Camera 4/2024-04-23/DCIM/101RECNX/RCNX3723.JPG | B16: N | C16: Y
A17: /Volumes/meadowbank_prod/remote_cameras/mbk_remote_cameras_blob/2024/FirstPart/Camera 4/2024-04-23/DCIM/101RECNX/RCNX3996.JPG | B17: N | C17: Y
A18: /Volumes/meadowbank_prod/remote_cameras/mbk_remote_cameras_blob/2024/FirstPart/Camera 17/2024-08-08/100RECNX/RCNX0199.JPG | B18: Y
A19: /Volumes/meadowbank_prod/remote_cameras/mbk_remote_cameras_blob/2024/FirstPart/Camera 14/2024-06-24/102RECNX/RCNX4406.JPG | B19: N
A20: /Volumes/meadowbank_prod/remote_cameras/mbk_remote_cameras_blob/2024/SecondPart/Camera/Camera 14/2024-09-14/100RECNX/RCNX1900.JPG | B20: N
A21: /Volumes/meadowbank_prod/remote_cameras/mbk_remote_cameras_blob/2024/SecondPart/Camera/Camera 13/2024-09-14/100RECNX/RCNX3097.JPG | B21: Y
A22: /Volumes/meadowbank_prod/remote_cameras/mbk_remote_cameras_blob/2024/FirstPart/Camera 17/2024-08-08/100RECNX/RCNX0225.JPG | B22: Y
A23: /Volumes/meadowbank_prod/remote_cameras/mbk_remote_cameras_blob/2024/FirstPart/Camera 13/2024-06-08/100RECNX/RCNX9021.JPG | B23: Y
A24: /Volumes/meadowbank_prod/remote_cameras/mbk_remote_cameras_blob/2024/FirstPart/Camera 17/2024-06-08/100RECNX/RCNX2935.JPG | B24: N
A25: /Volumes/meadowbank_prod/remote_cameras/mbk_remote_cameras_blob/2024/SecondPart/Camera/Camera 13/2024-09-14/100RECNX/RCNX3098.JPG | B25: Y
A26: /Volumes/meadowbank_prod/remote_cameras/mbk_remote_cameras_blob/2024/SecondPart/Camera/Camera 14/2024-09-21/100RECNX/RCNX0451.JPG | B26: N
A27: /Volumes/meadowbank_prod/remote_cameras/mbk_remote_cameras_blob/2024/FirstPart/Camera 14/2024-06-24/101RECNX/RCNX6321.JPG | B27: N
A28: /Volumes/meadowbank_prod/remote_cameras/mbk_remote_cameras_blob/2024/FirstPart/Camera 4/2024-05-05/100RECNX/RCNX4242.JPG | B28: N | C28: Y
A29: /Volumes/meadowbank_prod/remote_cameras/mbk_remote_cameras_blob/2024/FirstPart/Camera 4/2024-04-23/DCIM/101RECNX/RCNX3532.JPG | B29: N | C29: Y
A30: /Volumes/meadowbank_prod/remote_cameras/mbk_remote_cameras_blob/2024/SecondPart/Camera/Camera 14/2024-09-21/100RECNX/RCNX2554.JPG | B30: N
A31: /Volumes/meadowbank_prod/remote_cameras/mbk_remote_cameras_blob/2024/SecondPart/Camera/Camera 14/2024-10-05/100RECNX/RCNX7326.JPG | B31: N
A32: /Volumes/meadowbank_prod/remote_cameras/mbk_remote_cameras_blob/2024/SecondPart/Camera/Camera 18/2024-08-31/101RECNX/RCNX0254.JPG | B32: Y
A33: /Volumes/meadowbank_prod/remote_cameras/mbk_remote_cameras_blob/2024/FirstPart/Camera 4/2024-04-23/DCIM/101RECNX/RCNX8047.JPG | B33: N | C33: Y
A34: /Volumes/meadowbank_prod/remote_cameras/mbk_remote_cameras_blob/2024/FirstPart/Camera 18/2024-08-08/100RECNX/RCNX0109.JPG | B34: Y
A35: /Volumes/meadowbank_prod/remote_cameras/mbk_remote_cameras_blob/2024/FirstPart/Camera 17/2024-08-08/100RECNX/RCNX0342.JPG | B35: Y
A36: /Volumes/meadowbank_prod/remote_cameras/mbk_remote_cameras_blob/2024/SecondPart/Camera/Camera 11/2024-08-31/100RECNX/RCNX1463.JPG | B36: N
A37: /Volumes/meadowbank_prod/remote_cameras/mbk_remote_cameras_blob/2024/FirstPart/Camera 4/2024-05-05/100RECNX/RCNX3025.JPG | B37: N | C37: Y
A38: /Volumes/meadowbank_prod/remote_cameras/mbk_remote_cameras_blob/2024/FirstPart/Camera 17/2024-08-08/100RECNX/RCNX0156.JPG | B38: Y
A39: /Volumes/meadowbank_prod/remote_cameras/mbk_remote_cameras_blob/2024/FirstPart/Camera 17/2024-08-08/100RECNX/RCNX0290.JPG | B39: Y
A40: /Volumes/meadowbank_prod/remote_cameras/mbk_remote_cameras_blob/2024/SecondPart/Camera/Camera 14/2024-09-14/100RECNX/RCNX1157.JPG | B40: N
...

Sheet manual_validation_exclude_stati
A1: image_path | B1: contains_animals
A2: /Volumes/meadowbank_prod/remote_cameras/mbk_remote_cameras_blob/2024/FirstPart/Camera 12/2024-05-20/100RECNX/RCNX9952.JPG
A3: /Volumes/meadowbank_prod/remote_cameras/mbk_remote_cameras_blob/2024/SecondPart/Camera/Camera 14/2024-09-21/100RECNX/RCNX4237.JPG
A4: /Volumes/meadowbank_prod/remote_cameras/mbk_remote_cameras_blob/2024/FirstPart/Camera 14/2024-06-08/100RECNX/RCNX3034.JPG
A5: /Volumes/meadowbank_prod/remote_cameras/mbk_remote_cameras_blob/2024/SecondPart/Camera/Camera 13/2024-09-14/101RECNX/RCNX3683.JPG
A6: /Volumes/meadowbank_prod/remote_cameras/mbk_remote_cameras_blob/2024/SecondPart/Camera/Camera 14/2024-08-31/100RECNX/RCNX0649.JPG
A7: /Volumes/meadowbank_prod/remote_cameras/mbk_remote_cameras_blob/2024/FirstPart/Camera 14/2024-08-24/100RECNX/RCNX0326.JPG
A8: /Volumes/meadowbank_prod/remote_cameras/mbk_remote_cameras_blob/2024/SecondPart/Camera/Camera 13/2024-09-14/100RECNX/RCNX5736.JPG
A9: /Volumes/meadowbank_prod/remote_cameras/mbk_remote_cameras_blob/2024/FirstPart/Camera 11/2024-05-20/101RECNX/RCNX7660.JPG
A10: /Volumes/meadowbank_prod/remote_cameras/mbk_remote_cameras_blob/2024/FirstPart/Camera 19/2024-08-08/101RECNX/RCNX1241.JPG
A11: /Volumes/meadowbank_prod/remote_cameras/mbk_remote_cameras_blob/2024/SecondPart/Camera/Camera 8/2024-11-12/100RECNX/RCNX0433.JPG
A12: /Volumes/meadowbank_prod/remote_cameras/mbk_remote_cameras_blob/2024/FirstPart/Camera 17/2024-08-08/100RECNX/RCNX0296.JPG | B12: Y
A13: /Volumes/meadowbank_prod/remote_cameras/mbk_remote_cameras_blob/2024/FirstPart/Camera 18/2024-08-08/100RECNX/RCNX0119.JPG | B13: Y
A14: /Volumes/meadowbank_prod/remote_cameras/mbk_remote_cameras_blob/2024/FirstPart/Camera 17/2024-08-08/100RECNX/RCNX0193.JPG | B14: Y
A15: /Volumes/meadowbank_prod/remote_cameras/mbk_remote_cameras_blob/2024/FirstPart/Camera 17/2024-08-08/100RECNX/RCNX0212.JPG | B15: Y
A16: /Volumes/meadowbank_prod/remote_cameras/mbk_remote_cameras_blob/2024/FirstPart/Camera 14/2024-08-24/100RECNX/RCNX3637.JPG
A17: /Volumes/meadowbank_prod/remote_cameras/mbk_remote_cameras_blob/2024/FirstPart/Camera 18/2024-03-17/100RECNX/RCNX0305.JPG
A18: /Volumes/meadowbank_prod/remote_cameras/mbk_remote_cameras_blob/2024/FirstPart/Camera 17/2024-06-08/100RECNX/RCNX4090.JPG
A19: /Volumes/meadowbank_prod/remote_cameras/mbk_remote_cameras_blob/2024/SecondPart/Camera/Camera 13/2024-09-14/100RECNX/RCNX2880.JPG
A20: /Volumes/meadowbank_prod/remote_cameras/mbk_remote_cameras_blob/2024/FirstPart/Camera 6/2024-02-06/RCNX0001-2 (1909).JPG
A21: /Volumes/meadowbank_prod/remote_cameras/mbk_remote_cameras_blob/2024/SecondPart/Camera/Camera 14/2024-09-14/101RECNX/RCNX3024.JPG
A22: /Volumes/meadowbank_prod/remote_cameras/mbk_remote_cameras_blob/2024/FirstPart/Camera 18/2024-08-24/100RECNX/RCNX0233.JPG | B22: Y
A23: /Volumes/meadowbank_prod/remote_cameras/mbk_remote_cameras_blob/2024/FirstPart/Camera 18/2024-05-05/100RECNX/RCNX0503.JPG | B23: Y
A24: /Volumes/meadowbank_prod/remote_cameras/mbk_remote_cameras_blob/2024/FirstPart/Camera 17/2024-07-01/100RECNX/RCNX3767.JPG
A25: /Volumes/meadowbank_prod/remote_cameras/mbk_remote_cameras_blob/2024/FirstPart/Camera 19/2024-07-06/100RECNX/RCNX0400.JPG
A26: /Volumes/meadowbank_prod/remote_cameras/mbk_remote_cameras_blob/2024/SecondPart/Camera/Camera 18/2024-08-31/101RECNX/RCNX1074.JPG | B26: Y
A27: /Volumes/meadowbank_prod/remote_cameras/mbk_remote_cameras_blob/2024/FirstPart/Camera 14/2024-07-06/100RECNX/RCNX6140.JPG
A28: /Volumes/meadowbank_prod/remote_cameras/mbk_remote_cameras_blob/2024/FirstPart/Camera 17/2024-08-24/100RECNX/RCNX4040.JPG
A29: /Volumes/meadowbank_prod/remote_cameras/mbk_remote_cameras_blob/2024/FirstPart/Camera 18/2024-08-08/100RECNX/RCNX0261.JPG | B29: Y
A30: /Volumes/meadowbank_prod/remote_cameras/mbk_remote_cameras_blob/2024/FirstPart/Camera 12/2024-06-08/100RECNX/RCNX2850.JPG
A31: /Volumes/meadowbank_prod/remote_cameras/mbk_remote_cameras_blob/2024/SecondPart/Camera/Camera 14/2024-08-31/100RECNX/RCNX0612.JPG
A32: /Volumes/meadowbank_prod/remote_cameras/mbk_remote_cameras_blob/2024/FirstPart/Camera 19/2024-08-08/100RECNX/RCNX3061.JPG
A33: /Volumes/meadowbank_prod/remote_cameras/mbk_remote_cameras_blob/2024/FirstPart/Camera 18/2024-08-08/100RECNX/RCNX0102.JPG | B33: Y
A34: /Volumes/meadowbank_prod/remote_cameras/mbk_remote_cameras_blob/2024/SecondPart/Camera/Camera 13/2024-09-14/100RECNX/RCNX5826.JPG
A35: /Volumes/meadowbank_prod/remote_cameras/mbk_remote_cameras_blob/2024/FirstPart/Camera 17/2024-07-13/100RECNX/RCNX1070.JPG
A36: /Volumes/meadowbank_prod/remote_cameras/mbk_remote_cameras_blob/2024/FirstPart/Camera 18/2024-08-08/100RECNX/RCNX0324.JPG
A37: /Volumes/meadowbank_prod/remote_cameras/mbk_remote_cameras_blob/2024/FirstPart/Camera 1/2024-03-17/100RECNX/RCNX0433.JPG
A38: /Volumes/meadowbank_prod/remote_cameras/mbk_remote_cameras_blob/2024/FirstPart/Camera 14/2024-06-24/101RECNX/RCNX2730.JPG
A39: /Volumes/meadowbank_prod/remote_cameras/mbk_remote_cameras_blob/2024/FirstPart/Camera 19/2024-07-01/100RECNX/RCNX1048.JPG
A40: /Volumes/meadowbank_prod/remote_cameras/mbk_remote_cameras_blob/2024/FirstPart/Camera 12/2024-06-04/100RECNX/RCNX6488.JPG
...

Sheet manual_validation0.2_37
A1: image_path | B1: contains_animals
A2: /Volumes/meadowbank_prod/remote_cameras/mbk_remote_cameras_blob/2024/FirstPart/Camera 13/2024-05-05/100RECNX/RCNX0397.JPG | B2: Y
A3: /Volumes/meadowbank_prod/remote_cameras/mbk_remote_cameras_blob/2024/FirstPart/Camera 20/2024-07-01/100RECNX/RCNX0385.JPG | B3: Y
A4: /Volumes/meadowbank_prod/remote_cameras/mbk_remote_cameras_blob/2024/FirstPart/Camera 17/2024-08-08/100RECNX/RCNX0266.JPG | B4: Y
A5: /Volumes/meadowbank_prod/remote_cameras/mbk_remote_cameras_blob/2024/FirstPart/Camera 13/2024-06-08/100RECNX/RCNX3528.JPG
A6: /Volumes/meadowbank_prod/remote_cameras/mbk_remote_cameras_blob/2024/FirstPart/Camera 19/2024-08-08/100RECNX/RCNX6360.JPG
A7: /Volumes/meadowbank_prod/remote_cameras/mbk_remote_cameras_blob/2024/SecondPart/Camera/Camera 13/2024-09-14/100RECNX/RCNX3097.JPG
A8: /Volumes/meadowbank_prod/remote_cameras/mbk_remote_cameras_blob/2024/SecondPart/Camera/Camera 13/2024-09-14/100RECNX/RCNX3097.JPG | B8: Y
A9: /Volumes/meadowbank_prod/remote_cameras/mbk_remote_cameras_blob/2024/SecondPart/Camera/Camera 14/2024-09-21/100RECNX/RCNX0450.JPG | B9: Y
A10: /Volumes/meadowbank_prod/remote_cameras/mbk_remote_cameras_blob/2024/FirstPart/Camera 14/2024-08-24/100RECNX/RCNX9395.JPG
A11: /Volumes/meadowbank_prod/remote_cameras/mbk_remote_cameras_blob/2024/FirstPart/Camera 12/2024-05-20/100RECNX/RCNX6242.JPG
A12: /Volumes/meadowbank_prod/remote_cameras/mbk_remote_cameras_blob/2024/FirstPart/Camera 19/2024-07-01/100RECNX/RCNX8388.JPG
A13: /Volumes/meadowbank_prod/remote_cameras/mbk_remote_cameras_blob/2024/SecondPart/Camera/Camera 14/2024-09-14/100RECNX/RCNX3598.JPG
A14: /Volumes/meadowbank_prod/remote_cameras/mbk_remote_cameras_blob/2024/FirstPart/Camera 18/2024-08-08/100RECNX/RCNX0321.JPG | B14: Y
A15: /Volumes/meadowbank_prod/remote_cameras/mbk_remote_cameras_blob/2024/FirstPart/Camera 17/2024-08-08/100RECNX/RCNX0209.JPG | B15: Y
A16: /Volumes/meadowbank_prod/remote_cameras/mbk_remote_cameras_blob/2024/FirstPart/Camera 18/2024-08-08/100RECNX/RCNX0312.JPG | B16: Y
A17: /Volumes/meadowbank_prod/remote_cameras/mbk_remote_cameras_blob/2024/SecondPart/Camera/Camera 12/2024-11-12/100RECNX/RCNX6310.JPG
A18: /Volumes/meadowbank_prod/remote_cameras/mbk_remote_cameras_blob/2024/FirstPart/Camera 14/2024-06-08/100RECNX/RCNX3062.JPG
A19: /Volumes/meadowbank_prod/remote_cameras/mbk_remote_cameras_blob/2024/SecondPart/Camera/Camera 13/2024-09-14/100RECNX/RCNX3097.JPG | B19: Y
A20: /Volumes/meadowbank_prod/remote_cameras/mbk_remote_cameras_blob/2024/FirstPart/Camera 1/2024-06-24/100RECNX/RCNX3965.JPG
A21: /Volumes/meadowbank_prod/remote_cameras/mbk_remote_cameras_blob/2024/FirstPart/Camera 1/2024-06-24/100RECNX/RCNX3607.JPG
A22: /Volumes/meadowbank_prod/remote_cameras/mbk_remote_cameras_blob/2024/SecondPart/Camera/Camera 14/2024-09-21/100RECNX/RCNX2438.JPG
A23: /Volumes/meadowbank_prod/remote_cameras/mbk_remote_cameras_blob/2024/FirstPart/Camera 7/2024-06-24/100RECNX/RCNX1102.JPG | B23: Y
A24: /Volumes/meadowbank_prod/remote_cameras/mbk_remote_cameras_blob/2024/FirstPart/Camera 12/2024-06-04/100RECNX/RCNX5054.JPG
A25: /Volumes/meadowbank_prod/remote_cameras/mbk_remote_cameras_blob/2024/FirstPart/Camera 17/2024-08-08/100RECNX/RCNX0186.JPG | B25: Y
A26: /Volumes/meadowbank_prod/remote_cameras/mbk_remote_cameras_blob/2024/FirstPart/Camera 1/2024-05-29/100RECNX/RCNX2732.JPG
A27: /Volumes/meadowbank_prod/remote_cameras/mbk_remote_cameras_blob/2024/FirstPart/Camera 19/2024-07-01/100RECNX/RCNX8310.JPG
A28: /Volumes/meadowbank_prod/remote_cameras/mbk_remote_cameras_blob/2024/FirstPart/Camera 12/2024-06-04/100RECNX/RCNX4751.JPG
A29: /Volumes/meadowbank_prod/remote_cameras/mbk_remote_cameras_blob/2024/FirstPart/Camera 12/2024-06-08/100RECNX/RCNX4642.JPG
A30: /Volumes/meadowbank_prod/remote_cameras/mbk_remote_cameras_blob/2024/SecondPart/Camera/Camera 13/2024-09-14/101RECNX/RCNX5982.JPG
A31: /Volumes/meadowbank_prod/remote_cameras/mbk_remote_cameras_blob/2024/SecondPart/Camera/Camera 14/2024-09-21/100RECNX/RCNX7366.JPG
A32: /Volumes/meadowbank_prod/remote_cameras/mbk_remote_cameras_blob/2024/FirstPart/Camera 12/2024-06-08/100RECNX/RCNX3008.JPG
A33: /Volumes/meadowbank_prod/remote_cameras/mbk_remote_cameras_blob/2024/SecondPart/Camera/Camera 14/2024-09-14/100RECNX/RCNX7757.JPG
A34: /Volumes/meadowbank_prod/remote_cameras/mbk_remote_cameras_blob/2024/FirstPart/Camera 13/2024-05-05/100RECNX/RCNX0385.JPG | B34: Y
A35: /Volumes/meadowbank_prod/remote_cameras/mbk_remote_cameras_blob/2024/FirstPart/Camera 13/2024-05-05/100RECNX/RCNX0359.JPG | B35: Y
A36: /Volumes/meadowbank_prod/remote_cameras/mbk_remote_cameras_blob/2024/SecondPart/Camera/Camera 14/2024-09-14/100RECNX/RCNX4212.JPG
A37: /Volumes/meadowbank_prod/remote_cameras/mbk_remote_cameras_blob/2024/FirstPart/Camera 19/2024-06-24/102RECNX/RCNX1758.JPG
A38: /Volumes/meadowbank_prod/remote_cameras/mbk_remote_cameras_blob/2024/FirstPart/Camera 18/2024-08-08/100RECNX/RCNX0326.JPG | B38: Y
A39: /Volumes/meadowbank_prod/remote_cameras/mbk_remote_cameras_blob/2024/FirstPart/Camera 13/2024-05-05/100RECNX/RCNX0356.JPG | B39: Y
A40: /Volumes/meadowbank_prod/remote_cameras/mbk_remote_cameras_blob/2024/SecondPart/Camera/Camera 13/2024-09-14/100RECNX/RCNX3098.JPG | B40: Y
...

Sheet Post-processing Filter Static
A1: good example of static objects
A23: bad example of "static objects"
A57: Ideas:
A58: 1. Detect Static Images (your dataset has many)
A59: 2. Animal boxes tend to be rectangular but not extremely long or tall.
A60: bbox_w / bbox_h > 4
A61: bbox_h / bbox_w > 4

Sheet Design of Manifest Table
A1: Explanation of the numbers
B2: image_path | C2: file_size | D2: tm_indicator | E2: conf_detection_mg5a | F2: conf_detection_mg6b-yolo9c | G2: bbox_mg5a | H2: bbox_mg6_yologic | I2: pre-filtered | J2: final_category
A3: ='Waterfall Analyses'!B17-'Waterfall Analyses'!#REF! -> #REF! | B3: 1 | E3: no_detection | F3: no_detection | I3: yes | J3: pre_filtered
A4: ='Waterfall Analyses'!#REF! -> #REF! | B4: 2 | E4: 0.2 | F4: 0.2 | I4: no | J4: no_detection
A5: 511993 | B5: 3 | E5: 0.2 | F5: no_detection | I5: no | J5: no_detection
B6: 4 | D6: T | I6: yes | J6: pre_filtered
B7: 5 | C7: 103kb | I7: yes | J7: pre_filtered
A8: 30783 | B8: 6 | E8: 0.7 | F8: 0.7 | G8: [0.867, 0.802, 0.265, 0.284] | H8: [0.867, 0.802, 0.265, 0.284] | I8: no | J8: animal
B9: 7 | E9: 0.8 | F9: 0.6 | G9: [0.867, 0.802, 0.265, 0.284] | H9: [0.867, 0.802, 0.265, 0.284] | I9: no | J9: vehicle
A11: Final Table:
A12: image_path | K12: json_output
A13: /Volumes/meadowbank_prod/remote_cameras/mbk_remote_cameras_blob/2024/FirstPart/Camera 1/2024-05-29/100RECNX/RCNX8065.JPG | K13: {"category":"animals","conf_md5a":0.561,"bbox_md5a":[0.66,0.661,0.018,0.057],"conf_md9c":0.593,"bbox_md9c":[0.66,0.66,0.019,0.057]}, {"category":"vehicles","conf_md5a":0.776,"bbox_md5a":[0.917,0.59,0.167,0.316],"conf_md9c":0.607,"bbox_md9c":[0.917,0.597,0.167,0.299]}]

Sheet Model Comparison

Sheet Why not run 2models together
A1: Goal | B1: Recommended Setup
A2: Run MDv5 and MDv6 sequentially on the same cluster | B2: ✅ Yes. Finish MDv5 first → torch.cuda.empty_cache() → start MDv6
A3: Run both in parallel notebooks or jobs on same GPU | B3: ⚠️ Not recommended – T4 has insufficient VRAM
A4: Run both truly concurrently | B4: 🚫 Need ≥ 2 GPUs (e.g., Standard_NC24ads_A100_v4 or Standard_NC24s_v3)
A5: Share cluster for orchestration (CPU + I/O) | B5: ✅ Fine — the Spark driver/executor memory (83 GB) can handle two large DataFrames easily

Sheet v6b-yolo9c expected output

Sheet v5a expected output
